Traceback (most recent call last):
  File "/home/will/.local/lib/python3.6/site-packages/jupyter_cache/executors/utils.py", line 56, in single_nb_execution
    record_timing=False,
  File "/home/will/.local/lib/python3.6/site-packages/nbclient/client.py", line 1087, in execute
    return NotebookClient(nb=nb, resources=resources, km=km, **kwargs).execute()
  File "/home/will/.local/lib/python3.6/site-packages/nbclient/util.py", line 74, in wrapped
    return just_run(coro(*args, **kwargs))
  File "/home/will/.local/lib/python3.6/site-packages/nbclient/util.py", line 53, in just_run
    return loop.run_until_complete(coro)
  File "/usr/lib/python3.6/asyncio/base_events.py", line 484, in run_until_complete
    return future.result()
  File "/home/will/.local/lib/python3.6/site-packages/nbclient/client.py", line 541, in async_execute
    cell, index, execution_count=self.code_cells_executed + 1
  File "/home/will/.local/lib/python3.6/site-packages/nbclient/client.py", line 832, in async_execute_cell
    self._check_raise_for_error(cell, exec_reply)
  File "/home/will/.local/lib/python3.6/site-packages/nbclient/client.py", line 740, in _check_raise_for_error
    raise CellExecutionError.from_cell_and_msg(cell, exec_reply['content'])
nbclient.exceptions.CellExecutionError: An error occurred while executing the following cell:
------------------
# Load cgss2010 Stata file, display the first 5 rows (.head())
cgss = pd.read_stata('../data/cgss2010_12.dta', convert_categoricals=False)
cgss.info()
------------------

[0;31m---------------------------------------------------------------------------[0m
[0;31mFileNotFoundError[0m                         Traceback (most recent call last)
[0;32m<ipython-input-3-49c9eb9ec35f>[0m in [0;36m<module>[0;34m[0m
[1;32m      1[0m [0;31m# Load cgss2010 Stata file, display the first 5 rows (.head())[0m[0;34m[0m[0;34m[0m[0;34m[0m[0m
[0;32m----> 2[0;31m [0mcgss[0m [0;34m=[0m [0mpd[0m[0;34m.[0m[0mread_stata[0m[0;34m([0m[0;34m'../data/cgss2010_12.dta'[0m[0;34m,[0m [0mconvert_categoricals[0m[0;34m=[0m[0;32mFalse[0m[0;34m)[0m[0;34m[0m[0;34m[0m[0m
[0m[1;32m      3[0m [0mcgss[0m[0;34m.[0m[0minfo[0m[0;34m([0m[0;34m)[0m[0;34m[0m[0;34m[0m[0m

[0;32m~/anaconda3/lib/python3.8/site-packages/pandas/io/stata.py[0m in [0;36mread_stata[0;34m(filepath_or_buffer, convert_dates, convert_categoricals, index_col, convert_missing, preserve_dtypes, columns, order_categoricals, chunksize, iterator)[0m
[1;32m   1910[0m ) -> Union[DataFrame, StataReader]:
[1;32m   1911[0m [0;34m[0m[0m
[0;32m-> 1912[0;31m     reader = StataReader(
[0m[1;32m   1913[0m         [0mfilepath_or_buffer[0m[0;34m,[0m[0;34m[0m[0;34m[0m[0m
[1;32m   1914[0m         [0mconvert_dates[0m[0;34m=[0m[0mconvert_dates[0m[0;34m,[0m[0;34m[0m[0;34m[0m[0m

[0;32m~/anaconda3/lib/python3.8/site-packages/pandas/io/stata.py[0m in [0;36m__init__[0;34m(self, path_or_buf, convert_dates, convert_categoricals, index_col, convert_missing, preserve_dtypes, columns, order_categoricals, chunksize)[0m
[1;32m   1072[0m [0;34m[0m[0m
[1;32m   1073[0m         [0;32mif[0m [0misinstance[0m[0;34m([0m[0mpath_or_buf[0m[0;34m,[0m [0;34m([0m[0mstr[0m[0;34m,[0m [0mbytes[0m[0;34m)[0m[0;34m)[0m[0;34m:[0m[0;34m[0m[0;34m[0m[0m
[0;32m-> 1074[0;31m             [0mself[0m[0;34m.[0m[0mpath_or_buf[0m [0;34m=[0m [0mopen[0m[0;34m([0m[0mpath_or_buf[0m[0;34m,[0m [0;34m"rb"[0m[0;34m)[0m[0;34m[0m[0;34m[0m[0m
[0m[1;32m   1075[0m         [0;32melif[0m [0misinstance[0m[0;34m([0m[0mpath_or_buf[0m[0;34m,[0m [0mIOBase[0m[0;34m)[0m[0;34m:[0m[0;34m[0m[0;34m[0m[0m
[1;32m   1076[0m             [0;31m# Copy to BytesIO, and ensure no encoding[0m[0;34m[0m[0;34m[0m[0;34m[0m[0m

[0;31mFileNotFoundError[0m: [Errno 2] No such file or directory: '../data/cgss2010_12.dta'
FileNotFoundError: [Errno 2] No such file or directory: '../data/cgss2010_12.dta'

